[2024-10-12T18:31:01.931-0300] {local_task_job_runner.py:123} INFO - ::group::Pre task execution logs
[2024-10-12T18:31:01.944-0300] {taskinstance.py:2612} INFO - Dependencies all met for dep_context=non-requeueable deps ti=<TaskInstance: DesafioLH.export_final_output manual__2024-10-12T21:30:46.071524+00:00 [queued]>
[2024-10-12T18:31:01.950-0300] {taskinstance.py:2612} INFO - Dependencies all met for dep_context=requeueable deps ti=<TaskInstance: DesafioLH.export_final_output manual__2024-10-12T21:30:46.071524+00:00 [queued]>
[2024-10-12T18:31:01.951-0300] {taskinstance.py:2865} INFO - Starting attempt 1 of 2
[2024-10-12T18:31:01.972-0300] {taskinstance.py:2888} INFO - Executing <Task(PythonOperator): export_final_output> on 2024-10-12 21:30:46.071524+00:00
[2024-10-12T18:31:01.977-0300] {standard_task_runner.py:72} INFO - Started process 92615 to run task
[2024-10-12T18:31:01.984-0300] {standard_task_runner.py:104} INFO - Running: ['airflow', 'tasks', 'run', 'DesafioLH', 'export_final_output', 'manual__2024-10-12T21:30:46.071524+00:00', '--job-id', '87', '--raw', '--subdir', 'DAGS_FOLDER/desafiolh.py', '--cfg-path', '/tmp/tmpc2xl6fde']
[2024-10-12T18:31:01.987-0300] {standard_task_runner.py:105} INFO - Job 87: Subtask export_final_output
[2024-10-12T18:31:02.042-0300] {task_command.py:467} INFO - Running <TaskInstance: DesafioLH.export_final_output manual__2024-10-12T21:30:46.071524+00:00 [running]> on host LAPTOP-9RLTGE5V.
[2024-10-12T18:31:02.141-0300] {taskinstance.py:3131} INFO - Exporting env vars: AIRFLOW_CTX_DAG_EMAIL='kaue.oliveira@indicium.tech' AIRFLOW_CTX_DAG_OWNER='Kaue Oliveira' AIRFLOW_CTX_DAG_ID='DesafioLH' AIRFLOW_CTX_TASK_ID='export_final_output' AIRFLOW_CTX_EXECUTION_DATE='2024-10-12T21:30:46.071524+00:00' AIRFLOW_CTX_TRY_NUMBER='1' AIRFLOW_CTX_DAG_RUN_ID='manual__2024-10-12T21:30:46.071524+00:00'
[2024-10-12T18:31:02.142-0300] {taskinstance.py:731} INFO - ::endgroup::
[2024-10-12T18:31:02.158-0300] {taskinstance.py:3310} ERROR - Task failed with exception
Traceback (most recent call last):
  File "/home/kaueoliveira/desafiolh/airflow_tooltorial/venv/lib/python3.12/site-packages/airflow/models/taskinstance.py", line 767, in _execute_task
    result = _execute_callable(context=context, **execute_callable_kwargs)
             ^^^^^^^^^^^^^^^^^^^^^^^^^^^^^^^^^^^^^^^^^^^^^^^^^^^^^^^^^^^^^
  File "/home/kaueoliveira/desafiolh/airflow_tooltorial/venv/lib/python3.12/site-packages/airflow/models/taskinstance.py", line 733, in _execute_callable
    return ExecutionCallableRunner(
           ^^^^^^^^^^^^^^^^^^^^^^^^
  File "/home/kaueoliveira/desafiolh/airflow_tooltorial/venv/lib/python3.12/site-packages/airflow/utils/operator_helpers.py", line 252, in run
    return self.func(*args, **kwargs)
           ^^^^^^^^^^^^^^^^^^^^^^^^^^
  File "/home/kaueoliveira/desafiolh/airflow_tooltorial/venv/lib/python3.12/site-packages/airflow/models/baseoperator.py", line 406, in wrapper
    return func(self, *args, **kwargs)
           ^^^^^^^^^^^^^^^^^^^^^^^^^^^
  File "/home/kaueoliveira/desafiolh/airflow_tooltorial/venv/lib/python3.12/site-packages/airflow/operators/python.py", line 238, in execute
    return_value = self.execute_callable()
                   ^^^^^^^^^^^^^^^^^^^^^^^
  File "/home/kaueoliveira/desafiolh/airflow_tooltorial/venv/lib/python3.12/site-packages/airflow/operators/python.py", line 256, in execute_callable
    return runner.run(*self.op_args, **self.op_kwargs)
           ^^^^^^^^^^^^^^^^^^^^^^^^^^^^^^^^^^^^^^^^^^^
  File "/home/kaueoliveira/desafiolh/airflow_tooltorial/venv/lib/python3.12/site-packages/airflow/utils/operator_helpers.py", line 252, in run
    return self.func(*args, **kwargs)
           ^^^^^^^^^^^^^^^^^^^^^^^^^^
  File "/home/kaueoliveira/airflow/dags/desafiolh.py", line 28, in export_final_answer
    my_email = Variable.get("my_email")
               ^^^^^^^^^^^^^^^^^^^^^^^^
  File "/home/kaueoliveira/desafiolh/airflow_tooltorial/venv/lib/python3.12/site-packages/airflow/models/variable.py", line 145, in get
    raise KeyError(f"Variable {key} does not exist")
KeyError: 'Variable my_email does not exist'
[2024-10-12T18:31:02.174-0300] {taskinstance.py:1225} INFO - Marking task as UP_FOR_RETRY. dag_id=DesafioLH, task_id=export_final_output, run_id=manual__2024-10-12T21:30:46.071524+00:00, execution_date=20241012T213046, start_date=20241012T213101, end_date=20241012T213102
[2024-10-12T18:31:02.203-0300] {logging_mixin.py:190} WARNING - /home/kaueoliveira/desafiolh/airflow_tooltorial/venv/lib/python3.12/site-packages/airflow/utils/email.py:155 RemovedInAirflow3Warning: Fetching SMTP credentials from configuration variables will be deprecated in a future release. Please set credentials using a connection instead.
[2024-10-12T18:31:02.205-0300] {configuration.py:1058} WARNING - section/key [smtp/smtp_user] not found in config
[2024-10-12T18:31:02.205-0300] {email.py:272} INFO - Email alerting: attempt 1
[2024-10-12T18:31:02.218-0300] {configuration.py:1058} WARNING - section/key [smtp/smtp_user] not found in config
[2024-10-12T18:31:02.219-0300] {email.py:272} INFO - Email alerting: attempt 1
[2024-10-12T18:31:02.220-0300] {taskinstance.py:1234} ERROR - Failed to send email to: ['kaue.oliveira@indicium.tech']
Traceback (most recent call last):
  File "/home/kaueoliveira/desafiolh/airflow_tooltorial/venv/lib/python3.12/site-packages/airflow/models/taskinstance.py", line 273, in _run_raw_task
    TaskInstance._execute_task_with_callbacks(
  File "/home/kaueoliveira/desafiolh/airflow_tooltorial/venv/lib/python3.12/site-packages/airflow/models/taskinstance.py", line 3158, in _execute_task_with_callbacks
    result = self._execute_task(context, task_orig)
             ^^^^^^^^^^^^^^^^^^^^^^^^^^^^^^^^^^^^^^
  File "/home/kaueoliveira/desafiolh/airflow_tooltorial/venv/lib/python3.12/site-packages/airflow/models/taskinstance.py", line 3182, in _execute_task
    return _execute_task(self, context, task_orig)
           ^^^^^^^^^^^^^^^^^^^^^^^^^^^^^^^^^^^^^^^
  File "/home/kaueoliveira/desafiolh/airflow_tooltorial/venv/lib/python3.12/site-packages/airflow/models/taskinstance.py", line 767, in _execute_task
    result = _execute_callable(context=context, **execute_callable_kwargs)
             ^^^^^^^^^^^^^^^^^^^^^^^^^^^^^^^^^^^^^^^^^^^^^^^^^^^^^^^^^^^^^
  File "/home/kaueoliveira/desafiolh/airflow_tooltorial/venv/lib/python3.12/site-packages/airflow/models/taskinstance.py", line 733, in _execute_callable
    return ExecutionCallableRunner(
           ^^^^^^^^^^^^^^^^^^^^^^^^
  File "/home/kaueoliveira/desafiolh/airflow_tooltorial/venv/lib/python3.12/site-packages/airflow/utils/operator_helpers.py", line 252, in run
    return self.func(*args, **kwargs)
           ^^^^^^^^^^^^^^^^^^^^^^^^^^
  File "/home/kaueoliveira/desafiolh/airflow_tooltorial/venv/lib/python3.12/site-packages/airflow/models/baseoperator.py", line 406, in wrapper
    return func(self, *args, **kwargs)
           ^^^^^^^^^^^^^^^^^^^^^^^^^^^
  File "/home/kaueoliveira/desafiolh/airflow_tooltorial/venv/lib/python3.12/site-packages/airflow/operators/python.py", line 238, in execute
    return_value = self.execute_callable()
                   ^^^^^^^^^^^^^^^^^^^^^^^
  File "/home/kaueoliveira/desafiolh/airflow_tooltorial/venv/lib/python3.12/site-packages/airflow/operators/python.py", line 256, in execute_callable
    return runner.run(*self.op_args, **self.op_kwargs)
           ^^^^^^^^^^^^^^^^^^^^^^^^^^^^^^^^^^^^^^^^^^^
  File "/home/kaueoliveira/desafiolh/airflow_tooltorial/venv/lib/python3.12/site-packages/airflow/utils/operator_helpers.py", line 252, in run
    return self.func(*args, **kwargs)
           ^^^^^^^^^^^^^^^^^^^^^^^^^^
  File "/home/kaueoliveira/airflow/dags/desafiolh.py", line 28, in export_final_answer
    my_email = Variable.get("my_email")
               ^^^^^^^^^^^^^^^^^^^^^^^^
  File "/home/kaueoliveira/desafiolh/airflow_tooltorial/venv/lib/python3.12/site-packages/airflow/models/variable.py", line 145, in get
    raise KeyError(f"Variable {key} does not exist")
KeyError: 'Variable my_email does not exist'

During handling of the above exception, another exception occurred:

Traceback (most recent call last):
  File "/home/kaueoliveira/desafiolh/airflow_tooltorial/venv/lib/python3.12/site-packages/airflow/models/taskinstance.py", line 1442, in _email_alert
    send_email(task.email, subject, html_content)
  File "/home/kaueoliveira/desafiolh/airflow_tooltorial/venv/lib/python3.12/site-packages/airflow/utils/email.py", line 80, in send_email
    return backend(
           ^^^^^^^^
  File "/home/kaueoliveira/desafiolh/airflow_tooltorial/venv/lib/python3.12/site-packages/airflow/utils/email.py", line 155, in send_email_smtp
    send_mime_email(e_from=mail_from, e_to=recipients, mime_msg=msg, conn_id=conn_id, dryrun=dryrun)
  File "/home/kaueoliveira/desafiolh/airflow_tooltorial/venv/lib/python3.12/site-packages/airflow/utils/email.py", line 274, in send_mime_email
    smtp_conn = _get_smtp_connection(smtp_host, smtp_port, smtp_timeout, smtp_ssl)
                ^^^^^^^^^^^^^^^^^^^^^^^^^^^^^^^^^^^^^^^^^^^^^^^^^^^^^^^^^^^^^^^^^^
  File "/home/kaueoliveira/desafiolh/airflow_tooltorial/venv/lib/python3.12/site-packages/airflow/utils/email.py", line 318, in _get_smtp_connection
    return smtplib.SMTP(host=host, port=port, timeout=timeout)
           ^^^^^^^^^^^^^^^^^^^^^^^^^^^^^^^^^^^^^^^^^^^^^^^^^^^
  File "/usr/lib/python3.12/smtplib.py", line 255, in __init__
    (code, msg) = self.connect(host, port)
                  ^^^^^^^^^^^^^^^^^^^^^^^^
  File "/usr/lib/python3.12/smtplib.py", line 341, in connect
    self.sock = self._get_socket(host, port, self.timeout)
                ^^^^^^^^^^^^^^^^^^^^^^^^^^^^^^^^^^^^^^^^^^
  File "/usr/lib/python3.12/smtplib.py", line 312, in _get_socket
    return socket.create_connection((host, port), timeout,
           ^^^^^^^^^^^^^^^^^^^^^^^^^^^^^^^^^^^^^^^^^^^^^^^
  File "/usr/lib/python3.12/socket.py", line 852, in create_connection
    raise exceptions[0]
  File "/usr/lib/python3.12/socket.py", line 837, in create_connection
    sock.connect(sa)
ConnectionRefusedError: [Errno 111] Connection refused

During handling of the above exception, another exception occurred:

Traceback (most recent call last):
  File "/home/kaueoliveira/desafiolh/airflow_tooltorial/venv/lib/python3.12/site-packages/airflow/models/taskinstance.py", line 1232, in _handle_failure
    task_instance.email_alert(error, failure_context["task"])
  File "/home/kaueoliveira/desafiolh/airflow_tooltorial/venv/lib/python3.12/site-packages/airflow/models/taskinstance.py", line 3604, in email_alert
    _email_alert(task_instance=self, exception=exception, task=task)
  File "/home/kaueoliveira/desafiolh/airflow_tooltorial/venv/lib/python3.12/site-packages/airflow/models/taskinstance.py", line 1444, in _email_alert
    send_email(task.email, subject, html_content_err)
  File "/home/kaueoliveira/desafiolh/airflow_tooltorial/venv/lib/python3.12/site-packages/airflow/utils/email.py", line 80, in send_email
    return backend(
           ^^^^^^^^
  File "/home/kaueoliveira/desafiolh/airflow_tooltorial/venv/lib/python3.12/site-packages/airflow/utils/email.py", line 155, in send_email_smtp
    send_mime_email(e_from=mail_from, e_to=recipients, mime_msg=msg, conn_id=conn_id, dryrun=dryrun)
  File "/home/kaueoliveira/desafiolh/airflow_tooltorial/venv/lib/python3.12/site-packages/airflow/utils/email.py", line 274, in send_mime_email
    smtp_conn = _get_smtp_connection(smtp_host, smtp_port, smtp_timeout, smtp_ssl)
                ^^^^^^^^^^^^^^^^^^^^^^^^^^^^^^^^^^^^^^^^^^^^^^^^^^^^^^^^^^^^^^^^^^
  File "/home/kaueoliveira/desafiolh/airflow_tooltorial/venv/lib/python3.12/site-packages/airflow/utils/email.py", line 318, in _get_smtp_connection
    return smtplib.SMTP(host=host, port=port, timeout=timeout)
           ^^^^^^^^^^^^^^^^^^^^^^^^^^^^^^^^^^^^^^^^^^^^^^^^^^^
  File "/usr/lib/python3.12/smtplib.py", line 255, in __init__
    (code, msg) = self.connect(host, port)
                  ^^^^^^^^^^^^^^^^^^^^^^^^
  File "/usr/lib/python3.12/smtplib.py", line 341, in connect
    self.sock = self._get_socket(host, port, self.timeout)
                ^^^^^^^^^^^^^^^^^^^^^^^^^^^^^^^^^^^^^^^^^^
  File "/usr/lib/python3.12/smtplib.py", line 312, in _get_socket
    return socket.create_connection((host, port), timeout,
           ^^^^^^^^^^^^^^^^^^^^^^^^^^^^^^^^^^^^^^^^^^^^^^^
  File "/usr/lib/python3.12/socket.py", line 852, in create_connection
    raise exceptions[0]
  File "/usr/lib/python3.12/socket.py", line 837, in create_connection
    sock.connect(sa)
ConnectionRefusedError: [Errno 111] Connection refused
[2024-10-12T18:31:02.254-0300] {taskinstance.py:340} INFO - ::group::Post task execution logs
[2024-10-12T18:31:02.254-0300] {standard_task_runner.py:124} ERROR - Failed to execute job 87 for task export_final_output ('Variable my_email does not exist'; 92615)
Traceback (most recent call last):
  File "/home/kaueoliveira/desafiolh/airflow_tooltorial/venv/lib/python3.12/site-packages/airflow/task/task_runner/standard_task_runner.py", line 117, in _start_by_fork
    ret = args.func(args, dag=self.dag)
          ^^^^^^^^^^^^^^^^^^^^^^^^^^^^^
  File "/home/kaueoliveira/desafiolh/airflow_tooltorial/venv/lib/python3.12/site-packages/airflow/cli/cli_config.py", line 49, in command
    return func(*args, **kwargs)
           ^^^^^^^^^^^^^^^^^^^^^
  File "/home/kaueoliveira/desafiolh/airflow_tooltorial/venv/lib/python3.12/site-packages/airflow/utils/cli.py", line 115, in wrapper
    return f(*args, **kwargs)
           ^^^^^^^^^^^^^^^^^^
  File "/home/kaueoliveira/desafiolh/airflow_tooltorial/venv/lib/python3.12/site-packages/airflow/cli/commands/task_command.py", line 483, in task_run
    task_return_code = _run_task_by_selected_method(args, _dag, ti)
                       ^^^^^^^^^^^^^^^^^^^^^^^^^^^^^^^^^^^^^^^^^^^^
  File "/home/kaueoliveira/desafiolh/airflow_tooltorial/venv/lib/python3.12/site-packages/airflow/cli/commands/task_command.py", line 256, in _run_task_by_selected_method
    return _run_raw_task(args, ti)
           ^^^^^^^^^^^^^^^^^^^^^^^
  File "/home/kaueoliveira/desafiolh/airflow_tooltorial/venv/lib/python3.12/site-packages/airflow/cli/commands/task_command.py", line 341, in _run_raw_task
    return ti._run_raw_task(
           ^^^^^^^^^^^^^^^^^
  File "/home/kaueoliveira/desafiolh/airflow_tooltorial/venv/lib/python3.12/site-packages/airflow/utils/session.py", line 97, in wrapper
    return func(*args, session=session, **kwargs)
           ^^^^^^^^^^^^^^^^^^^^^^^^^^^^^^^^^^^^^^
  File "/home/kaueoliveira/desafiolh/airflow_tooltorial/venv/lib/python3.12/site-packages/airflow/models/taskinstance.py", line 3004, in _run_raw_task
    return _run_raw_task(
           ^^^^^^^^^^^^^^
  File "/home/kaueoliveira/desafiolh/airflow_tooltorial/venv/lib/python3.12/site-packages/airflow/models/taskinstance.py", line 273, in _run_raw_task
    TaskInstance._execute_task_with_callbacks(
  File "/home/kaueoliveira/desafiolh/airflow_tooltorial/venv/lib/python3.12/site-packages/airflow/models/taskinstance.py", line 3158, in _execute_task_with_callbacks
    result = self._execute_task(context, task_orig)
             ^^^^^^^^^^^^^^^^^^^^^^^^^^^^^^^^^^^^^^
  File "/home/kaueoliveira/desafiolh/airflow_tooltorial/venv/lib/python3.12/site-packages/airflow/models/taskinstance.py", line 3182, in _execute_task
    return _execute_task(self, context, task_orig)
           ^^^^^^^^^^^^^^^^^^^^^^^^^^^^^^^^^^^^^^^
  File "/home/kaueoliveira/desafiolh/airflow_tooltorial/venv/lib/python3.12/site-packages/airflow/models/taskinstance.py", line 767, in _execute_task
    result = _execute_callable(context=context, **execute_callable_kwargs)
             ^^^^^^^^^^^^^^^^^^^^^^^^^^^^^^^^^^^^^^^^^^^^^^^^^^^^^^^^^^^^^
  File "/home/kaueoliveira/desafiolh/airflow_tooltorial/venv/lib/python3.12/site-packages/airflow/models/taskinstance.py", line 733, in _execute_callable
    return ExecutionCallableRunner(
           ^^^^^^^^^^^^^^^^^^^^^^^^
  File "/home/kaueoliveira/desafiolh/airflow_tooltorial/venv/lib/python3.12/site-packages/airflow/utils/operator_helpers.py", line 252, in run
    return self.func(*args, **kwargs)
           ^^^^^^^^^^^^^^^^^^^^^^^^^^
  File "/home/kaueoliveira/desafiolh/airflow_tooltorial/venv/lib/python3.12/site-packages/airflow/models/baseoperator.py", line 406, in wrapper
    return func(self, *args, **kwargs)
           ^^^^^^^^^^^^^^^^^^^^^^^^^^^
  File "/home/kaueoliveira/desafiolh/airflow_tooltorial/venv/lib/python3.12/site-packages/airflow/operators/python.py", line 238, in execute
    return_value = self.execute_callable()
                   ^^^^^^^^^^^^^^^^^^^^^^^
  File "/home/kaueoliveira/desafiolh/airflow_tooltorial/venv/lib/python3.12/site-packages/airflow/operators/python.py", line 256, in execute_callable
    return runner.run(*self.op_args, **self.op_kwargs)
           ^^^^^^^^^^^^^^^^^^^^^^^^^^^^^^^^^^^^^^^^^^^
  File "/home/kaueoliveira/desafiolh/airflow_tooltorial/venv/lib/python3.12/site-packages/airflow/utils/operator_helpers.py", line 252, in run
    return self.func(*args, **kwargs)
           ^^^^^^^^^^^^^^^^^^^^^^^^^^
  File "/home/kaueoliveira/airflow/dags/desafiolh.py", line 28, in export_final_answer
    my_email = Variable.get("my_email")
               ^^^^^^^^^^^^^^^^^^^^^^^^
  File "/home/kaueoliveira/desafiolh/airflow_tooltorial/venv/lib/python3.12/site-packages/airflow/models/variable.py", line 145, in get
    raise KeyError(f"Variable {key} does not exist")
KeyError: 'Variable my_email does not exist'
[2024-10-12T18:31:02.317-0300] {local_task_job_runner.py:266} INFO - Task exited with return code 1
[2024-10-12T18:31:02.330-0300] {taskinstance.py:3900} INFO - 0 downstream tasks scheduled from follow-on schedule check
[2024-10-12T18:31:02.331-0300] {local_task_job_runner.py:245} INFO - ::endgroup::
